Workbook

Sheet 01_הסבר
A1: מיפוי הסברי אבחון לדוח הורים — מה המנוע אומר ומה ההורה רואה
A3: מטרה
A4: הקובץ מרכז את 50 אבחוני הטקסונומיה של מנוע האבחון בדוח הורים. לכל אבחון מופיעים: ההבחנה המקצועית, מה המנוע מזהה/אומר, מה ההורה רואה בדוח, ומה שורת ההסבר המאושרת שמתווספת רק אם אותו אבחון באמת הופיע אצל הילד/ה.
A9: כלל מוצרי חשוב
A10: לא מחליפים את שם האבחון המקצועי. לא מציגים מילון כללי. אם המנוע אבחן X — ההורה רואה את תווית/דפוס הקושי ובנוסף שורת הסבר קצרה שאושרה. אם המנוע לא אבחן X — לא מופיע הסבר על X. דוגמאות/תרגילים צריכים להופיע בשורה נפרדת ולא באמצע משפט עברי.
A17: סטטוס | B17: משמעות | C17: פעולה
A18: מיושם ומאושר | B18: ההסבר כבר אושר ונוסף לשכבת ההסברים | C18: נדרש רק בדיקת מסך לפי הצורך
A19: ממתין ליישום/אישור | B19: נוסח מוכן בטבלה אבל לא דווח עדיין כמיושם | C19: להעביר לביצוע/אישור לפני הפעלה
A20: לא רלוונטי | B20: אין אבחון כזה בדוח הספציפי | C20: לא מוצג להורה
A21: לא ממופה | B21: אם יופיע אבחון לא מוכר | C21: לא להמציא הסבר

Sheet 02_מיפוי_מלא
A1: מקצוע | B1: קוד | C1: מפתח lookup | D1: הבחנה מקצועית | E1: מה המנוע אומר / מזהה | F1: מה ההורה רואה בדוח | G1: הסבר להורה | H1: דוגמה כללית | I1: סטטוס | J1: מקור אישור | K1: הערות
A2: מתמטיקה | B2: M-01 | C2: finding:taxonomy:M-01 | D2: מבנה/פירוק — פירוק 10+1 | E2: טעויות בהמרת ייצוג | F2: בדוח הורים: תווית הקושי שהמנוע מצא + הסבר מאושר מתחתיה | G2: המערכת זיהתה קושי בפירוק מספר לעשרות ויחידות. הכוונה היא להבין שמספר מורכב מעשרות ויחידות, כדי להשתמש בזה בחישוב. | H2: 14 = 10 + 4 | I2: מיושם ומאושר | J2: owner_math_batch_approved | K2: התווית המקצועית נשארת; ההסבר מופיע רק אם M-01 אובחן.
A3: מתמטיקה | B3: M-02 | C3: finding:taxonomy:M-02 | D3: חיבור — נשיאה | E3: שגיאה בעמודת עשרות | F3: בדוח הורים ההורה לרוב רואה: שגיאה בעמודת עשרות; מתחתיה הסבר מאושר | G3: המערכת זיהתה קושי בחיבור שבו צריך להעביר עשרת לעמודה הבאה. זה קורה כשמחברים ספרות ומתקבל מספר גדול מ־9. | H3: 27 + 18 | I3: מיושם ומאושר | J3: owner_math_batch_approved | K3: נשיאה נשארת אבחון מקצועי; ההורה מקבל פירוש קצר.
A4: מתמטיקה | B4: M-03 | C4: finding:taxonomy:M-03 | D4: כפל — עובדת כפל | E4: אותם זוגות שגויים | F4: בדוח הורים: דפוס של זוגות כפל שחוזרים עם טעויות + הסבר מאושר | G4: המערכת זיהתה קושי בשליפה של תרגילי כפל בסיסיים. הכוונה היא לזוגות מספרים בכפל שכדאי לדעת במהירות ובדיוק, בלי לחשב מההתחלה בכל פעם. | H4: 7 × 8 | I4: מיושם ומאושר | J4: owner_math_batch_approved
A5: מתמטיקה | B5: M-04 | C5: finding:taxonomy:M-04 | D5: שברים — חלק־כלל | E5: השוואה לפי מונה בלבד | F5: בדוח הורים: קושי בשברים/חלק־כלל + הסבר מאושר | G5: המערכת זיהתה קושי בהבנה ששבר מייצג חלק מתוך שלם. חשוב להבין שהמספר התחתון אומר לכמה חלקים השלם חולק, והמספר העליון אומר כמה חלקים נלקחו. | H5: 2/3 | I5: מיושם ומאושר | J5: owner_math_batch_approved
A6: מתמטיקה | B6: M-05 | C6: finding:taxonomy:M-05 | D6: שברים — המראה | E6: טעות בשלב התאמת מכנה/המראה | F6: בדוח הורים: קושי בשברים עם מכנים שונים + הסבר מאושר | G6: המערכת זיהתה קושי בחיבור או חיסור שברים כשצריך להביא אותם לאותו מכנה לפני החישוב. כלומר, לא מחברים מיד את המונים והמכנים, אלא קודם כותבים את השברים באותו סוג חלקים. | H6: 1/2 + 1/3 | I6: מיושם ומאושר | J6: owner_math_batch_approved | K6: לא משנים את המונח המקצועי 'המראה'.
A7: מתמטיקה | B7: M-06 | C7: finding:taxonomy:M-06 | D7: עשרוניים — עיגול/השוואה | E7: בלבול בכיוון העיגול | F7: בדוח הורים: קושי בעיגול/השוואה של עשרוניים + הסבר מאושר | G7: המערכת זיהתה קושי בעיגול או בהשוואה של מספרים עשרוניים. הכוונה היא להבין את הספרות שאחרי הנקודה ולדעת לפי איזו ספרה מחליטים אם לעגל למעלה או להשאיר. | H7: 4.67 → 4.7 | I7: מיושם ומאושר | J7: owner_math_batch_approved
A8: מתמטיקה | B8: M-07 | C8: finding:taxonomy:M-07 | D8: בעיות מילוליות — יחידות | E8: מספר נכון + יחידה שגויה | F8: בדוח הורים: קושי בהתאמת יחידות בתשובה + הסבר מאושר | G8: המערכת זיהתה קושי בהתאמת יחידת המידה לתשובה. ייתכן שהחישוב המספרי נכון, אבל צריך לבדוק אם התשובה צריכה להיות בקילוגרמים, מטרים, שקלים, דקות וכדומה. | H8: 5 ק״מ / 5 ק״ג | I8: מיושם ומאושר | J8: owner_math_batch_approved
A9: מתמטיקה | B9: M-08 | C9: finding:taxonomy:M-08 | D9: בעיות מילוליות — רב־שלבי | E9: כישלון רק באיחוד/בשילוב שלבים | F9: בדוח הורים: קושי בבעיה עם כמה שלבים + הסבר מאושר | G9: המערכת זיהתה קושי בפתרון בעיות מילוליות שיש בהן יותר משלב אחד. הכוונה היא לזהות מה צריך לעשות קודם, להשתמש בתוצאה, ואז להמשיך לשלב הבא. | H9: קנייה + עודף | I9: מיושם ומאושר | J9: owner_math_batch_approved
A10: מתמטיקה | B10: M-09 | C10: finding:taxonomy:M-09 | D10: חיסור — השלמה לעשר | E10: כיוון הפוך / הוספה במקום חיסור | F10: בדוח הורים: קושי באסטרטגיית השלמה לעשר + הסבר מאושר | G10: המערכת זיהתה קושי בשימוש בעשר הקרובה כדי לחשב חיסור. הכוונה היא לפרק את החיסור לצעדים קטנים, קודם להגיע לעשר ואז להמשיך לחסר. | H10: 13 - 5 | I10: מיושם ומאושר | J10: owner_math_batch_approved
A11: מתמטיקה | B11: M-10 | C11: finding:taxonomy:M-10 | D11: חילוק — הופכיות | E11: קושי בקישור בין כפל לחילוק | F11: בדוח הורים: קושי בקשר חילוק/כפל + הסבר מאושר | G11: המערכת זיהתה קושי בהבנת הקשר בין חילוק לכפל. כלומר, להשתמש בכפל כדי לבדוק תרגיל חילוק או לבחור את הפעולה המתאימה. | H11: 12 ÷ 3 = 4; 4 × 3 = 12 | I11: מיושם ומאושר | J11: owner_math_batch_approved | K11: דוגמת תרגיל חייבת להופיע בשורה נפרדת עם כיוון LTR.
A12: גיאומטריה | B12: G-01 | C12: finding:taxonomy:G-01 | D12: מרובעים — תכונות מלבן/מקבילית | E12: בלבול תכונות | F12: בדוח הורים: תווית הקושי שהמנוע מצא + הסבר מאושר מתחתיה | G12: המערכת זיהתה קושי בהבחנה בין תכונות של מרובעים. הכוונה היא לדעת אילו צלעות מקבילות, אילו זוויות ישרות, ומה ההבדל בין מלבן, ריבוע ומקבילית. | H12: מלבן / מקבילית | I12: מיושם ומאושר | J12: owner_geometry_batch_approved
A13: גיאומטריה | B13: G-02 | C13: finding:taxonomy:G-02 | D13: זוויות — קריאת משקף | E13: טעות בקריאת זווית במשקף | F13: בדוח הורים: תווית הקושי שהמנוע מצא + הסבר מאושר מתחתיה | G13: המערכת זיהתה קושי בקריאת זווית בעזרת משקף. הכוונה היא להצמיד נכון את מרכז המשקף ואת קו האפס, ואז לקרוא את המספר מהסולם המתאים. | H13: 40° | I13: מיושם ומאושר | J13: owner_geometry_batch_approved
A14: גיאומטריה | B14: G-03 | C14: finding:taxonomy:G-03 | D14: שטח — גובה | E14: צלעות כגובה | F14: בדוח הורים: תווית הקושי שהמנוע מצא + הסבר מאושר מתחתיה | G14: המערכת זיהתה קושי בזיהוי הגובה המתאים לחישוב שטח. בגיאומטריה גובה הוא קו שניצב לבסיס, ולא תמיד הצלע שנראית הכי ארוכה או אלכסונית. | H14: גובה ⟂ בסיס | I14: מיושם ומאושר | J14: owner_geometry_batch_approved
A15: גיאומטריה | B15: G-04 | C15: finding:taxonomy:G-04 | D15: סיבוב — כיוון/זווית | E15: סיבוב הפוך | F15: בדוח הורים: תווית הקושי שהמנוע מצא + הסבר מאושר מתחתיה | G15: המערכת זיהתה קושי בזיהוי כיוון הסיבוב או גודל הסיבוב. הכוונה היא להבין אם הצורה מסתובבת עם כיוון השעון או נגדו, ובכמה מעלות. | H15: 90° ימינה | I15: מיושם ומאושר | J15: owner_geometry_batch_approved
A16: גיאומטריה | B16: G-05 | C16: finding:taxonomy:G-05 | D16: נפח — מודל תלת־ממדי | E16: שוכח עומק | F16: בדוח הורים: תווית הקושי שהמנוע מצא + הסבר מאושר מתחתיה | G16: המערכת זיהתה קושי בהבנת גוף תלת־ממדי. הכוונה היא לראות שלא מדובר רק בציור שטוח, אלא בצורה שיש לה אורך, רוחב וגובה. | H16: קובייה | I16: מיושם ומאושר | J16: owner_geometry_batch_approved
A17: גיאומטריה | B17: G-06 | C17: finding:taxonomy:G-06 | D17: היקף — המרת יחידות | E17: טעות יחידה חוזרת | F17: בדוח הורים: תווית הקושי שהמנוע מצא + הסבר מאושר מתחתיה | G17: המערכת זיהתה קושי בהמרת יחידות לפני חישוב היקף או אורך. הכוונה היא לוודא שכל המידות באותה יחידה לפני שמחברים או משווים. | H17: 120 ס״מ = 1.2 מ׳ | I17: מיושם ומאושר | J17: owner_geometry_batch_approved
A18: גיאומטריה | B18: G-07 | C18: finding:taxonomy:G-07 | D18: סימטריה — ציר | E18: ציר שגוי חוזר | F18: בדוח הורים: תווית הקושי שהמנוע מצא + הסבר מאושר מתחתיה | G18: המערכת זיהתה קושי בזיהוי ציר סימטריה. הכוונה היא למצוא קו שמחלק את הצורה לשני חלקים זהים, כך שאפשר לקפל לאורך הקו ושני הצדדים יתאימו. | H18: קו קיפול באמצע צורה | I18: מיושם ומאושר | J18: owner_geometry_batch_approved
A19: גיאומטריה | B19: G-08 | C19: finding:taxonomy:G-08 | D19: משולשים — בסיס×גובה÷2 | E19: שוכח ÷2 או גובה שגוי | F19: בדוח הורים: תווית הקושי שהמנוע מצא + הסבר מאושר מתחתיה | G19: המערכת זיהתה קושי בחישוב שטח משולש. כדי למצוא שטח משולש משתמשים בבסיס ובגובה המתאים, ואז מחלקים את התוצאה ב־2. | H19: בסיס 6, גובה 4: 6 × 4 ÷ 2 | I19: מיושם ומאושר | J19: owner_geometry_batch_approved
A20: עברית | B20: H-01 | C20: finding:taxonomy:H-01 | D20: עברית — נרדפת | E20: מילה קרובה לא נכונה | F20: בדוח הורים: תווית הקושי שהמנוע מצא + הסבר מאושר מתחתיה | G20: המערכת זיהתה קושי בבחירת מילה נרדפת שמתאימה להקשר. הכוונה היא לא רק למצוא מילה דומה, אלא לוודא שהיא מתאימה למשמעות המשפט. | H20: שמח / עליז | I20: מיושם ומאושר | J20: owner_hebrew_subject_batch_approved
A21: עברית | B21: H-02 | C21: finding:taxonomy:H-02 | D21: דקדוק — מגדר/מספר | E21: כינוי/שם עצם שגוי | F21: בדוח הורים: תווית הקושי שהמנוע מצא + הסבר מאושר מתחתיה | G21: המערכת זיהתה קושי בהתאמה בין מילים במשפט לפי מין ומספר. הכוונה היא לוודא שהשם, התואר או הכינוי מתאימים לזכר או נקבה, וליחיד או רבים. | H21: ילדה קטנה / ילדים קטנים | I21: מיושם ומאושר | J21: owner_hebrew_subject_batch_approved
A22: עברית | B22: H-03 | C22: finding:taxonomy:H-03 | D22: כתיב — משפחת כתיב | E22: אותה משפחה שגויה | F22: בדוח הורים: תווית הקושי שהמנוע מצא + הסבר מאושר מתחתיה | G22: המערכת זיהתה קושי בזיהוי משפחת מילים או תבנית כתיב שחוזרת במילים קשורות. הכוונה היא לשים לב לאותיות ולמבנה שחוזרים באותה משפחת מילים. | H22: כתב / מכתב / כתיבה | I22: מיושם ומאושר | J22: owner_hebrew_subject_batch_approved
A23: עברית | B23: H-04 | C23: finding:taxonomy:H-04 | D23: הבנת הנקרא — חיפוש | E23: קריאת השאלה לא הייתה מסודרת | F23: בדוח הורים: תווית הקושי שהמנוע מצא + הסבר מאושר מתחתיה | G23: המערכת זיהתה קושי באיתור מידע בתוך טקסט. הכוונה היא למצוא פרט מסוים לפי מילות מפתח, כותרות או רמזים שמופיעים בשאלה ובטקסט. | H23: מתי קרה? / מי עשה? | I23: מיושם ומאושר | J23: owner_hebrew_subject_batch_approved
... A27: עברית | B27: H-08 | C27: finding:taxonomy:H-08 | D27: עברית — פורמליות | E27: רמת לשון לא מתאימה | F27: בדוח הורים: תווית הקושי שהמנוע מצא + הסבר מאושר מתחתיה | G27: המערכת זיהתה קושי בהתאמת רמת הלשון למצב. הכוונה היא לבחור ניסוח שמתאים למטרה: שיחה יומיומית, תשובה לימודית או פנייה רשמית. | H27: אפשר לקבל עזרה? / תביא לי | I27: מיושם ומאושר | J27: owner_hebrew_subject_batch_approved
A28: אנגלית | B28: E-01 | C28: finding:taxonomy:E-01 | D28: אנגלית — collocation | E28: תרגום מילולי שגוי | F28: בדוח הורים: התווית המקצועית/דפוס הקושי + הסבר מאושר מתחתיה | G28: המערכת זיהתה קושי בשימוש בצירופי מילים טבעיים באנגלית. הכוונה היא שיש מילים שבאנגלית רגילים לומר יחד, ולא תמיד אפשר לתרגם מילה במילה מעברית. | H28: make a decision | I28: מיושם ומאושר | J28: owner_english_subject_batch_approved | K28: תוויות מקצועיות באנגלית אינן מוחלפות; רק מוסיפים הסבר בעברית.
A29: אנגלית | B29: E-02 | C29: finding:taxonomy:E-02 | D29: אנגלית — סממן זמן | E29: past/present או בחירת זמן לא מתאימה | F29: בדוח הורים: התווית המקצועית/דפוס הקושי + הסבר מאושר מתחתיה | G29: המערכת זיהתה קושי בזיהוי רמזים שמראים באיזה זמן המשפט כתוב. הכוונה היא לשים לב למילים שמראות אם מדובר בעבר, בהווה או בעתיד, ואז לבחור את צורת הפועל המתאימה. | H29: yesterday / now / tomorrow | I29: מיושם ומאושר | J29: owner_english_subject_batch_approved | K29: תוויות מקצועיות באנגלית אינן מוחלפות; רק מוסיפים הסבר בעברית.
A30: אנגלית | B30: E-03 | C30: finding:taxonomy:E-03 | D30: אנגלית — מעקב שורות | E30: טעות במעקב אחרי השורה הנכונה | F30: בדוח הורים: התווית המקצועית/דפוס הקושי + הסבר מאושר מתחתיה | G30: המערכת זיהתה קושי במעקב אחרי המקום הנכון בטקסט באנגלית. הכוונה היא לקרוא לפי הסדר, לא לדלג שורה, ולחזור לשורה המתאימה כשמחפשים תשובה. | H30: line 3 | I30: מיושם ומאושר | J30: owner_english_subject_batch_approved | K30: תוויות מקצועיות באנגלית אינן מוחלפות; רק מוסיפים הסבר בעברית.
A31: אנגלית | B31: E-04 | C31: finding:taxonomy:E-04 | D31: אנגלית — כינוי לנושא | E31: he/she/it | F31: בדוח הורים: התווית המקצועית/דפוס הקושי + הסבר מאושר מתחתיה | G31: המערכת זיהתה קושי בבחירת כינוי הגוף המתאים לנושא המשפט באנגלית. הכוונה היא לבחור נכון בין כינויים כמו הוא, היא או זה לפי מי או מה שמדברים עליו. | H31: he / she / it | I31: מיושם ומאושר | J31: owner_english_subject_batch_approved | K31: תוויות מקצועיות באנגלית אינן מוחלפות; רק מוסיפים הסבר בעברית.
A32: אנגלית | B32: E-05 | C32: finding:taxonomy:E-05 | D32: אנגלית — preposition | E32: מילת יחס שגויה | F32: בדוח הורים: התווית המקצועית/דפוס הקושי + הסבר מאושר מתחתיה | G32: המערכת זיהתה קושי בשימוש במילות יחס באנגלית. אלו מילים קצרות שמראות קשר של מקום, זמן או כיוון, ולעיתים הן לא מתורגמות ישירות מעברית. | H32: in / on / at | I32: מיושם ומאושר | J32: owner_english_subject_batch_approved | K32: תוויות מקצועיות באנגלית אינן מוחלפות; רק מוסיפים הסבר בעברית.
A33: אנגלית | B33: E-06 | C33: finding:taxonomy:E-06 | D33: אנגלית — inference | E33: קושי בהבנת משמעות משתמעת | F33: בדוח הורים: התווית המקצועית/דפוס הקושי + הסבר מאושר מתחתיה | G33: המערכת זיהתה קושי בהבנת מסקנה מתוך טקסט באנגלית. הכוונה היא להבין דבר שלא כתוב במפורש, אלא משתמע מתוך המשפטים והרמזים בטקסט. | H33: The room is dark, so she turns on the light. | I33: מיושם ומאושר | J33: owner_english_subject_batch_approved | K33: תוויות מקצועיות באנגלית אינן מוחלפות; רק מוסיפים הסבר בעברית.
A34: אנגלית | B34: E-07 | C34: finding:taxonomy:E-07 | D34: אנגלית — תבניות שקטות | E34: שגיאות חוזרות באיות/צליל | F34: בדוח הורים: התווית המקצועית/דפוס הקושי + הסבר מאושר מתחתיה | G34: המערכת זיהתה קושי בזיהוי אותיות או תבניות כתיב באנגלית שלא תמיד שומעים בהגייה. הכוונה היא לשים לב לכך שלא כל אות במילה נשמעת כמו שהיא נכתבת. | H34: knight / night | I34: מיושם ומאושר | J34: owner_english_subject_batch_approved | K34: תוויות מקצועיות באנגלית אינן מוחלפות; רק מוסיפים הסבר בעברית.
A35: אנגלית | B35: E-08 | C35: finding:taxonomy:E-08 | D35: אנגלית — minimal pairs | E35: בלבול צמד צלילים | F35: בדוח הורים: התווית המקצועית/דפוס הקושי + הסבר מאושר מתחתיה | G35: המערכת זיהתה קושי בהבחנה בין מילים באנגלית שנשמעות כמעט אותו דבר, אבל שונות בצליל קטן ובמשמעות. הכוונה היא להקשיב להבדל המדויק בין הצלילים. | H35: ship / sheep | I35: מיושם ומאושר | J35: owner_english_subject_batch_approved | K35: תוויות מקצועיות באנגלית אינן מוחלפות; רק מוסיפים הסבר בעברית.
A36: מדעים | B36: S-01 | C36: finding:taxonomy:S-01 | D36: מדעים — תכונה מול תהליך | E36: בלבול קטגוריה | F36: בדוח הורים: תווית הקושי שהמנוע מצא + הסבר מאושר מתחתיה | G36: המערכת זיהתה קושי בהבחנה בין תכונה של דבר לבין תהליך שקורה לו. תכונה מתארת מה מאפיין חומר, גוף או יצור, ותהליך מתאר שינוי או פעולה שמתרחשים לאורך זמן. | H36: צבע הוא תכונה; התכה היא תהליך | I36: מיושם ומאושר | J36: owner_science_subject_batch_approved
A37: מדעים | B37: S-02 | C37: finding:taxonomy:S-02 | D37: מדעים — משתנה מבודד | E37: שינוי כמה גורמים בניסוי | F37: בדוח הורים: תווית הקושי שהמנוע מצא + הסבר מאושר מתחתיה | G37: המערכת זיהתה קושי בהבנת ניסוי שבו משנים רק גורם אחד בכל פעם. הכוונה היא להשאיר את שאר התנאים קבועים, כדי לדעת מה באמת השפיע על התוצאה. | H37: משנים רק את כמות האור | I37: מיושם ומאושר | J37: owner_science_subject_batch_approved
A38: מדעים | B38: S-03 | C38: finding:taxonomy:S-03 | D38: מדעים — מיקום/זרימה | E38: סדר/מיקום שגוי | F38: בדוח הורים: תווית הקושי שהמנוע מצא + הסבר מאושר מתחתיה | G38: המערכת זיהתה קושי בהבנת מיקום או סדר זרימה בתוך מערכת. הכוונה היא לדעת איפה נמצא כל חלק ומה הסדר שבו חומר, מידע או פעולה עוברים ממקום למקום. | H38: לב → כלי דם | I38: מיושם ומאושר | J38: owner_science_subject_batch_approved
A39: מדעים | B39: S-04 | C39: finding:taxonomy:S-04 | D39: מדעים — שימור מסה | E39: חומר נעלם בלי שימור | F39: בדוח הורים: תווית הקושי שהמנוע מצא + הסבר מאושר מתחתיה | G39: המערכת זיהתה קושי בהבנה שחומר לא נעלם כאשר הוא משתנה. במקרים רבים החומר משנה צורה, מצב או מקום, אבל הכמות הכוללת שלו נשמרת. | H39: קרח → מים | I39: מיושם ומאושר | J39: owner_science_subject_batch_approved
A40: מדעים | B40: S-05 | C40: finding:taxonomy:S-05 | D40: מדעים — המרת יחידות | E40: בלבול יחידות | F40: בדוח הורים: תווית הקושי שהמנוע מצא + הסבר מאושר מתחתיה | G40: המערכת זיהתה קושי בשימוש נכון ביחידות מדידה ובהמרה ביניהן. הכוונה היא לבדוק אם מודדים אורך, מסה, זמן או נפח, ולהשתמש ביחידה המתאימה. | H40: 1000 גרם = 1 ק״ג | I40: מיושם ומאושר | J40: owner_science_subject_batch_approved
A41: מדעים | B41: S-06 | C41: finding:taxonomy:S-06 | D41: מדעים — קריאת ציר | E41: טעות בערך מגרף | F41: בדוח הורים: תווית הקושי שהמנוע מצא + הסבר מאושר מתחתיה | G41: המערכת זיהתה קושי בקריאת ערכים מתוך גרף. הכוונה היא להבין מה כל ציר מייצג, למצוא את הנקודה המתאימה, ולקרוא ממנה את הערך הנכון. | H41: ציר X / ציר Y | I41: מיושם ומאושר | J41: owner_science_subject_batch_approved
A42: מדעים | B42: S-07 | C42: finding:taxonomy:S-07 | D42: מדעים — רשת מזון | E42: רמה שגויה חוזרת | F42: בדוח הורים: תווית הקושי שהמנוע מצא + הסבר מאושר מתחתיה | G42: המערכת זיהתה קושי בהבנת קשרי אכילה והעברת אנרגיה בטבע. הכוונה היא לזהות מי אוכל את מי, ומה התפקיד של כל יצור במערכת. | H42: צמח → ארנב → שועל | I42: מיושם ומאושר | J42: owner_science_subject_batch_approved
A43: מדעים | B43: S-08 | C43: finding:taxonomy:S-08 | D43: מדעים — מקור לטענה | E43: טענה לא מבוססת | F43: בדוח הורים: תווית הקושי שהמנוע מצא + הסבר מאושר מתחתיה | G43: המערכת זיהתה קושי בביסוס תשובה על מקור מידע. הכוונה היא לא להסתפק בתחושה או ניחוש, אלא למצוא בטקסט, בתצפית או בנתונים מה תומך בטענה. | H43: לפי הטקסט / לפי התצפית | I43: מיושם ומאושר | J43: owner_science_subject_batch_approved
...

Sheet 03_סיכום
A1: סיכום לפי מקצוע
A3: מקצוע | B3: סה״כ אבחונים | C3: מיושם ומאושר | D3: ממתין | E3: אחוז מיושם | F3: הערה
A4: מתמטיקה | B4: =COUNTIF('02_מיפוי_מלא'!$A:$A,A4) | C4: =COUNTIFS('02_מיפוי_מלא'!$A:$A,A4,'02_מיפוי_מלא'!$I:$I,"מיושם ומאושר") | D4: =COUNTIFS('02_מיפוי_מלא'!$A:$A,A4,'02_מיפוי_מלא'!$I:$I,"ממתין ליישום/אישור") | E4: =IF(B4=0,0,C4/B4) | F4: בוצע
A5: גיאומטריה | B5: =COUNTIF('02_מיפוי_מלא'!$A:$A,A5) | C5: =COUNTIFS('02_מיפוי_מלא'!$A:$A,A5,'02_מיפוי_מלא'!$I:$I,"מיושם ומאושר") | D5: =COUNTIFS('02_מיפוי_מלא'!$A:$A,A5,'02_מיפוי_מלא'!$I:$I,"ממתין ליישום/אישור") | E5: =IF(B5=0,0,C5/B5) | F5: בוצע
A6: עברית | B6: =COUNTIF('02_מיפוי_מלא'!$A:$A,A6) | C6: =COUNTIFS('02_מיפוי_מלא'!$A:$A,A6,'02_מיפוי_מלא'!$I:$I,"מיושם ומאושר") | D6: =COUNTIFS('02_מיפוי_מלא'!$A:$A,A6,'02_מיפוי_מלא'!$I:$I,"ממתין ליישום/אישור") | E6: =IF(B6=0,0,C6/B6) | F6: בוצע
A7: אנגלית | B7: =COUNTIF('02_מיפוי_מלא'!$A:$A,A7) | C7: =COUNTIFS('02_מיפוי_מלא'!$A:$A,A7,'02_מיפוי_מלא'!$I:$I,"מיושם ומאושר") | D7: =COUNTIFS('02_מיפוי_מלא'!$A:$A,A7,'02_מיפוי_מלא'!$I:$I,"ממתין ליישום/אישור") | E7: =IF(B7=0,0,C7/B7) | F7: בוצע
A8: מדעים | B8: =COUNTIF('02_מיפוי_מלא'!$A:$A,A8) | C8: =COUNTIFS('02_מיפוי_מלא'!$A:$A,A8,'02_מיפוי_מלא'!$I:$I,"מיושם ומאושר") | D8: =COUNTIFS('02_מיפוי_מלא'!$A:$A,A8,'02_מיפוי_מלא'!$I:$I,"ממתין ליישום/אישור") | E8: =IF(B8=0,0,C8/B8) | F8: בוצע
A9: מולדת/גאוגרפיה | B9: =COUNTIF('02_מיפוי_מלא'!$A:$A,A9) | C9: 8 | D9: 0 | E9: 1 | F9: בוצע
A10: סה״כ | B10: =SUM(B4:B9) | C10: 50 | D10: 0 | E10: 1 | F10: כל 50 האבחונים מיושמים ומאושרים

Sheet 04_כללי_תצוגה
A1: כללי תצוגה ויישום
A3: כלל | B3: מה עושים | C3: מה לא עושים
A4: הצגת הסבר | B4: מציגים רק אם אותו finding אובחן בפועל בדוח ההורים. | C4: לא מציגים הסברים לנושאים שלא אובחנו.
A5: תווית מקצועית | B5: משאירים את שם האבחון/דפוס המנוע כמו שהוא. | C5: לא משנים/מחליפים מונחים מקצועיים כמו נשיאה, collocation או שימור מסה.
A6: עברית | B6: משתמשים רק בנוסח עברי שאושר מראש. | C6: לא נותנים ל־Cursor לנסח לבד.
A7: מיקום | B7: בדוח הקצר: מתחת לשורת הקושי. בדוח המפורט: ליד/מתחת לאבחון הגלוי. | C7: לא בתוך המלצות פעולה, מטרות שבועיות או גלוסרי.
A8: דוגמאות | B8: דוגמה בשורה נפרדת עם טיפול כיוון מתאים. | C8: לא לשים תרגיל באמצע משפט עברי.
A9: דוחות אחרים | B9: השינוי הוא לדוח הורים בלבד. | C9: לא לגעת בדוחות מורים/בית ספר/מנהל/כיתה.
A10: לא ממופה | B10: אם אין key מאושר — לא מציגים הסבר. | C10: לא להמציא טקסט מילוי.
